<?xml version="1.0" ?>
<!-- =================================================================================== -->
<!-- |    This document was autogenerated by xacro from routewise.urdf.xacro           | -->
<!-- |    EDITING THIS FILE BY HAND IS NOT RECOMMENDED                                 | -->
<!-- =================================================================================== -->
<robot name="routewise">
  <!-- Material Definitions -->
  <material name="blue">
    <color rgba="0 0 1 1"/>
  </material>
  <material name="grey">
    <color rgba="0.5 0.5 0.5 1"/>
  </material>
  <!-- Base Link -->
  <link name="base_link">
    <visual>
      <geometry>
        <box size="0.5 0.5 0.1"/>
      </geometry>
      <material name="blue"/>
    </visual>
    <collision>
      <geometry>
        <box size="0.5 0.5 0.1"/>
      </geometry>
    </collision>
  </link>
  <link name="front_left_wheel">
    <visual>
      <geometry>
        <cylinder length="0.05" radius="0.075"/>
      </geometry>
      <material name="grey"/>
    </visual>
    <collision>
      <geometry>
        <cylinder length="0.05" radius="0.075"/>
      </geometry>
    </collision>
  </link>
  <link name="front_right_wheel">
    <visual>
      <geometry>
        <cylinder length="0.05" radius="0.075"/>
      </geometry>
      <material name="grey"/>
    </visual>
    <collision>
      <geometry>
        <cylinder length="0.05" radius="0.075"/>
      </geometry>
    </collision>
  </link>
  <link name="rear_left_wheel">
    <visual>
      <geometry>
        <cylinder length="0.05" radius="0.075"/>
      </geometry>
      <material name="grey"/>
    </visual>
    <collision>
      <geometry>
        <cylinder length="0.05" radius="0.075"/>
      </geometry>
    </collision>
  </link>
  <link name="rear_right_wheel">
    <visual>
      <geometry>
        <cylinder length="0.05" radius="0.075"/>
      </geometry>
      <material name="grey"/>
    </visual>
    <collision>
      <geometry>
        <cylinder length="0.05" radius="0.075"/>
      </geometry>
    </collision>
  </link>
  <joint name="front_left_wheel_joint" type="continuous">
    <parent link="base_link"/>
    <child link="front_left_wheel"/>
    <origin rpy="0 0 0" xyz="0.25 0.25 0"/>
    <axis xyz="0 0 1"/>
  </joint>
  <joint name="front_right_wheel_joint" type="continuous">
    <parent link="base_link"/>
    <child link="front_right_wheel"/>
    <origin rpy="0 0 0" xyz="0.25 -0.25 0"/>
    <axis xyz="0 0 1"/>
  </joint>
  <joint name="rear_left_wheel_joint" type="continuous">
    <parent link="base_link"/>
    <child link="rear_left_wheel"/>
    <origin rpy="0 0 0" xyz="-0.25 0.25 0"/>
    <axis xyz="0 0 1"/>
  </joint>
  <joint name="rear_right_wheel_joint" type="continuous">
    <parent link="base_link"/>
    <child link="rear_right_wheel"/>
    <origin rpy="0 0 0" xyz="-0.25 -0.25 0"/>
    <axis xyz="0 0 1"/>
  </joint>
  <!-- Additional robot components, sensors, etc., can be added here -->
</robot>
