<?xml version="1.0"?>
<robot xmlns:xacro="http://ros.org/wiki/xacro">

    <!-- Parameters -->
    <xacro:property name="base_length" value="0.5"/>
    <xacro:property name="base_width" value="0.5"/>
    <xacro:property name="base_height" value="0.1"/>
    <xacro:property name="wheel_radius" value="0.075"/>
    <xacro:property name="wheel_width" value="0.05"/>

    <!-- Base Link -->
    <link name="base_link">
        <visual>
            <geometry>
                <box size="${base_length} ${base_width} ${base_height}"/>
            </geometry>
            <material name="blue"/>
        </visual>
        <collision>
            <geometry>
                <box size="${base_length} ${base_width} ${base_height}"/>
            </geometry>
        </collision>
    </link>

    <!-- Wheel Link Macro -->
    <xacro:macro name="wheel_link" params="name">
        <link name="${name}">
            <visual>
                <geometry>
                    <cylinder radius="${wheel_radius}" length="${wheel_width}"/>
                </geometry>
                <material name="grey"/>
            </visual>
            <collision>
                <geometry>
                    <cylinder radius="${wheel_radius}" length="${wheel_width}"/>
                </geometry>
            </collision>
        </link>
    </xacro:macro>

    <!-- Wheel Joint Macro -->
    <xacro:macro name="wheel_joint" params="name parent child xyz">
        <joint name="${name}" type="continuous">
            <parent link="${parent}"/>
            <child link="${child}"/>
            <origin xyz="${xyz}" rpy="0 0 0"/>
            <axis xyz="0 0 1"/>
        </joint>
    </xacro:macro>

    <!-- Wheel Links and Joints -->
    <xacro:wheel_link name="front_left_wheel"/>
    <xacro:wheel_link name="front_right_wheel"/>
    <xacro:wheel_link name="rear_left_wheel"/>
    <xacro:wheel_link name="rear_right_wheel"/>

    <xacro:wheel_joint name="front_left_wheel_joint" parent="base_link" child="front_left_wheel" xyz="0.25 0.25 0"/>
    <xacro:wheel_joint name="front_right_wheel_joint" parent="base_link" child="front_right_wheel" xyz="0.25 -0.25 0"/>
    <xacro:wheel_joint name="rear_left_wheel_joint" parent="base_link" child="rear_left_wheel" xyz="-0.25 0.25 0"/>
    <xacro:wheel_joint name="rear_right_wheel_joint" parent="base_link" child="rear_right_wheel" xyz="-0.25 -0.25 0"/>

</robot>
